Workbook

Sheet 2-1
A1: [ 問題２ ] ( 1 ) | C1: 実行終了後のレジスタと各番地の内容
B3: GR2 | C3: 0001 | E3: PROG | F3: START
B4: GR3 | C4: 000D | F4: LD | G4: GR2,N
F5: LD | G5: GR3,DATA2
B6: DATA1 | C6: 1120 | F6: ADDA | G6: GR3,GR2
B7: DATA2 | C7: 000C | F7: ST | G7: GR3,ANS
B8: DATA3 | C8: 1403 | F8: RET
B9: DATA4 | C9: 8100 | E9: DATA1 | F9: DC | G9: #1120
B10: N | C10: 0001 | E10: DATA2 | F10: DC | G10: #000C
B11: ANS | C11: 000D | E11: DATA3 | F11: DC | G11: #1403
E12: DATA4 | F12: DC | G12: #8100
E13: N | F13: DC | G13: 1
E14: ANS | F14: DS | G14: 1
F15: END

Sheet 2-2
A1: [ 問題２ ] ( 2 ) | C1: ロード直後の主記憶の内容
B3: アドレス(16進数) | C3: 主記憶装置
B4: 0000 | C4: 1020
B5: 0001 | C5: 000C
B6: 0002 | C6: 1030
B7: 0003 | C7: 0009
B8: 0004 | C8: 2432
B9: 0005 | C9: 1130
B10: 0006 | C10: 000D
B11: 0007 | C11: 8100
B12: 0008 | C12: 1120
B13: 0009 | C13: 000C
B14: 000A | C14: 1403
... B17: 000D | C17: ****

Sheet 2-3
A1: [ 問題２ ] ( 3 ) | C1: 実行後の主記憶とレジスタの内容
B3: アドレス(16進数) | C3: 主記憶装置 | G3: 左記のようになった理由
B4: 0000 | C4: 1020 | E4: GR0 | G4: #0006番地までは(2)と同じように進んでいくが、[RET]がないため、そのままデータ部分を実行命令として受け取って進めていく。なので、#0007番地の「ST GR2,#000C」では#000C番地にGR2のデータ(0001)を格納して#000C番地に0001、#0009番地の「LD GR0,GR3」はGR0にGR3の内容を読み込ませGR0が000Dとなる。その後、#000A番地のもともとデータだった[8100]がRET命令として受け取られて、プログラムの書き込みが終了するため、実行が終了される。
B5: 0001 | C5: 000B | E5: 000D
B6: 0002 | C6: 1030 | E6: GR2
B7: 0003 | C7: 0008 | E7: 0001
B8: 0004 | C8: 2432 | E8: GR3
B9: 0005 | C9: 1130 | E9: 000D
B10: 0006 | C10: 000C
B11: 0007 | C11: 1120
B12: 0008 | C12: 000C
B13: 0009 | C13: 1403
B14: 000A | C14: 8100
B15: 000B | C15: 0001
B16: 000C | C16: 0001

Sheet 3
A1: [ 問題３ ] | C1: 逆アセンブル
B3: アドレス | C3: 機械語 | F3: OP | G3: オペランド
B4: 0000: | C4: 1200 | D4: 0000 | F4: LAD | G4: GR0, #0000
B5: 0002: | C5: 1010 | D5: 0010 | F5: LD | G5: GR1, #0010
B6: 0004: | C6: 1220 | D6: 0001 | F6: LAD | G6: GR2, #0001
B7: 0006: | C7: 2512 | F7: SUBA | G7: GR1, GR2
B8: 0007: | C8: 6100 | D8: 000D | F8: JMI | G8: #000D
B9: 0009: | C9: 2001 | D9: 0012 | F9: ADDA | G9: GR0, #0012, GR1
B10: 000B: | C10: 6400 | D10: 0006 | F10: JUMP | G10: #0006
B11: 000D: | C11: 1100 | D11: 0011 | F11: ST | G11: GR0, #0011
B12: 000F: | C12: 8100 | F12: RET

Sheet Sheet1
A1: [ 問題２ ] ( 1 ) | C1: 実行終了後のレジスタと各番地の内容
B3: GR2 | C3: =IF('2-1'!C3="","",ASC(UPPER(RIGHT(TRIM('2-1'!C3),4)))) -> 0001 | E3: 0001 | F3: =IF(C3<>E3,"×","")
B4: GR3 | C4: =IF('2-1'!C4="","",ASC(UPPER(RIGHT(TRIM('2-1'!C4),4)))) -> 000D | E4: 000D | F4: =IF(C4<>E4,"×","")
B6: DATA1 | C6: =IF('2-1'!C6="","",ASC(UPPER(RIGHT(TRIM('2-1'!C6),4)))) -> 1120 | E6: 1120 | F6: =IF(C6<>E6,"×","")
B7: DATA2 | C7: =IF('2-1'!C7="","",ASC(UPPER(RIGHT(TRIM('2-1'!C7),4)))) -> 000C | E7: 000C | F7: =IF(C7<>E7,"×","")
B8: DATA3 | C8: =IF('2-1'!C8="","",ASC(UPPER(RIGHT(TRIM('2-1'!C8),4)))) -> 1403 | E8: 1403 | F8: =IF(C8<>E8,"×","")
B9: DATA4 | C9: =IF('2-1'!C9="","",ASC(UPPER(RIGHT(TRIM('2-1'!C9),4)))) -> 8100 | E9: 8100 | F9: =IF(C9<>E9,"×","")
B10: N | C10: =IF('2-1'!C10="","",ASC(UPPER(RIGHT(TRIM('2-1'!C10),4)))) -> 0001 | E10: 0001 | F10: =IF(C10<>E10,"×","") | H10: {=_xlfn.TEXTJOIN(",",TRUE,IF(F3:F11="×",B3:B11,""))}
B11: ANS | C11: =IF('2-1'!C11="","",ASC(UPPER(RIGHT(TRIM('2-1'!C11),4)))) -> 000D | E11: 000D | F11: =IF(C11<>E11,"×","") | H11: =IF(H10="","",H10&"が異なる。")
A14: [ 問題２ ] ( 2 ) | C14: ロード直後の主記憶の内容
B16: アドレス(16進数) | C16: 主記憶装置
B17: 0000 | C17: =IF('2-2'!C4="","",ASC(UPPER(RIGHT(TRIM('2-2'!C4),4)))) -> 1020 | E17: 1020 | F17: =IF(C17<>E17,"×","")
B18: 0001 | C18: =IF('2-2'!C5="","",ASC(UPPER(RIGHT(TRIM('2-2'!C5),4)))) -> 000C | E18: 000C | F18: =IF(C18<>E18,"×","")
B19: 0002 | C19: =IF('2-2'!C6="","",ASC(UPPER(RIGHT(TRIM('2-2'!C6),4)))) -> 1030 | E19: 1030 | F19: =IF(C19<>E19,"×","")
B20: 0003 | C20: =IF('2-2'!C7="","",ASC(UPPER(RIGHT(TRIM('2-2'!C7),4)))) -> 0009 | E20: 0009 | F20: =IF(C20<>E20,"×","")
B21: 0004 | C21: =IF('2-2'!C8="","",ASC(UPPER(RIGHT(TRIM('2-2'!C8),4)))) -> 2432 | E21: 2432 | F21: =IF(C21<>E21,"×","")
B22: 0005 | C22: =IF('2-2'!C9="","",ASC(UPPER(RIGHT(TRIM('2-2'!C9),4)))) -> 1130 | E22: 1130 | F22: =IF(C22<>E22,"×","")
B23: 0006 | C23: =IF('2-2'!C10="","",ASC(UPPER(RIGHT(TRIM('2-2'!C10),4)))) -> 000D | E23: 000D | F23: =IF(C23<>E23,"×","")
B24: 0007 | C24: =IF('2-2'!C11="","",ASC(UPPER(RIGHT(TRIM('2-2'!C11),4)))) -> 8100 | E24: 8100 | F24: =IF(C24<>E24,"×","")
B25: 0008 | C25: =IF('2-2'!C12="","",ASC(UPPER(RIGHT(TRIM('2-2'!C12),4)))) -> 1120 | E25: 1120 | F25: =IF(C25<>E25,"×","")
B26: 0009 | C26: =IF('2-2'!C13="","",ASC(UPPER(RIGHT(TRIM('2-2'!C13),4)))) -> 000C | E26: 000C | F26: =IF(C26<>E26,"×","")
B27: 000A | C27: =IF('2-2'!C14="","",ASC(UPPER(RIGHT(TRIM('2-2'!C14),4)))) -> 1403 | E27: 1403 | F27: =IF(C27<>E27,"×","")
B28: 000B | C28: =IF('2-2'!C15="","",ASC(UPPER(RIGHT(TRIM('2-2'!C15),4)))) -> 8100 | E28: 8100 | F28: =IF(C28<>E28,"×","")
B29: 000C | C29: =IF('2-2'!C16="","",ASC(UPPER(RIGHT(TRIM('2-2'!C16),4)))) -> 0001 | E29: 0001 | F29: =IF(C29<>E29,"×","") | H29: {=_xlfn.TEXTJOIN(",",TRUE,IF(F17:F30="×",B17:B30,""))}
B30: 000D | C30: =IF('2-2'!C17="","",ASC(UPPER(RIGHT(TRIM('2-2'!C17),4)))) -> **** | E30: **** | F30: =IF(C30<>E30,"×","") | H30: =IF(H29="","",H29&"が異なる。")
A32: [ 問題２ ] ( 3 ) | C32: 実行後の主記憶とレジスタの内容
B34: アドレス(16進数) | C34: 主記憶装置 | H34: 左記のようになった理由
B35: 0000 | C35: =IF('2-3'!C4="","",ASC(UPPER(RIGHT(TRIM('2-3'!C4),4)))) -> 1020 | E35: 1020 | F35: =IF(C35<>E35,"×","") | H35: ='2-3'!G4 -> #0006番地までは(2)と同じように進んでいくが、[RET]がないため、そのままデータ部分を実行命令として受け取って進めていく。なので、#0007番地の「ST GR2,#000C」では#000C番地にGR2のデータ(0001)を格納して#000C番地に0001、#0009番地の「LD GR0,GR3」はGR0にGR3の内容を読み込ませGR0が000Dとなる。その後、#000A番地のもともとデータだった[8100]がRET命令として受け取られて、プログラムの書き込みが終了するため、実行が終了される。 | J35: RET命令がないので、本来はデータである１１２０ ０００Cが機械語として認識される。１１２０ ０００CはGR2の内容を０００Cに転送するという命令なので０００Cに0001が入る。さらに１４０３が機械語として認識され、GR0にGR3の内容が読み込まれて０００Dが入る。
B36: 0001 | C36: =IF('2-3'!C5="","",ASC(UPPER(RIGHT(TRIM('2-3'!C5),4)))) -> 000B | E36: 000B | F36: =IF(C36<>E36,"×","")
B37: 0002 | C37: =IF('2-3'!C6="","",ASC(UPPER(RIGHT(TRIM('2-3'!C6),4)))) -> 1030 | E37: 1030 | F37: =IF(C37<>E37,"×","")
B38: 0003 | C38: =IF('2-3'!C7="","",ASC(UPPER(RIGHT(TRIM('2-3'!C7),4)))) -> 0008 | E38: 0008 | F38: =IF(C38<>E38,"×","")
B39: 0004 | C39: =IF('2-3'!C8="","",ASC(UPPER(RIGHT(TRIM('2-3'!C8),4)))) -> 2432 | E39: 2432 | F39: =IF(C39<>E39,"×","")
B40: 0005 | C40: =IF('2-3'!C9="","",ASC(UPPER(RIGHT(TRIM('2-3'!C9),4)))) -> 1130 | E40: 1130 | F40: =IF(C40<>E40,"×","")
B41: 0006 | C41: =IF('2-3'!C10="","",ASC(UPPER(RIGHT(TRIM('2-3'!C10),4)))) -> 000C | E41: 000C | F41: =IF(C41<>E41,"×","")
B42: 0007 | C42: =IF('2-3'!C11="","",ASC(UPPER(RIGHT(TRIM('2-3'!C11),4)))) -> 1120 | E42: 1120 | F42: =IF(C42<>E42,"×","")
B43: 0008 | C43: =IF('2-3'!C12="","",ASC(UPPER(RIGHT(TRIM('2-3'!C12),4)))) -> 000C | E43: 000C | F43: =IF(C43<>E43,"×","")
B44: 0009 | C44: =IF('2-3'!C13="","",ASC(UPPER(RIGHT(TRIM('2-3'!C13),4)))) -> 1403 | E44: 1403 | F44: =IF(C44<>E44,"×","")
B45: 000A | C45: =IF('2-3'!C14="","",ASC(UPPER(RIGHT(TRIM('2-3'!C14),4)))) -> 8100 | E45: 8100 | F45: =IF(C45<>E45,"×","")
B46: 000B | C46: =IF('2-3'!C15="","",ASC(UPPER(RIGHT(TRIM('2-3'!C15),4)))) -> 0001 | E46: 0001 | F46: =IF(C46<>E46,"×","")
B47: 000C | C47: =IF('2-3'!C16="","",ASC(UPPER(RIGHT(TRIM('2-3'!C16),4)))) -> 0001 | E47: 0001 | F47: =IF(C47<>E47,"×","")
...
